../env.sh: line 4: activate: No such file or directory
The following values were not passed to `accelerate launch` and had defaults used instead:
		More than one GPU was found, enabling multi-GPU training.
		If this was unintended please pass in `--num_processes=1`.
	`--num_machines` was set to a value of `1`
	`--mixed_precision` was set to a value of `'no'`
	`--dynamo_backend` was set to a value of `'no'`
To avoid this warning pass in values for each of the problematic parameters or run `accelerate config`.
usage: text_to_image.py [-h] [--dist_inference DIST_INFERENCE]
                        [--img_save_dir IMG_SAVE_DIR]
usage: text_to_image.py [-h] [--dist_inference DIST_INFERENCE]
                        [--img_save_dir IMG_SAVE_DIR]
text_to_image.py: error: argument --dist_inference: expected one argument
text_to_image.py: error: argument --dist_inference: expected one argument
ERROR:torch.distributed.elastic.multiprocessing.api:failed (exitcode: 2) local_rank: 0 (pid: 664523) of binary: /home/bingxing2/home/scx6002/.conda/envs/test_sd_benchmark/bin/python3.8
Traceback (most recent call last):
  File "/home/bingxing2/home/scx6002/.conda/envs/test_sd_benchmark/bin/accelerate", line 8, in <module>
    sys.exit(main())
  File "/home/bingxing2/home/scx6002/.conda/envs/test_sd_benchmark/lib/python3.8/site-packages/accelerate/commands/accelerate_cli.py", line 45, in main
    args.func(args)
  File "/home/bingxing2/home/scx6002/.conda/envs/test_sd_benchmark/lib/python3.8/site-packages/accelerate/commands/launch.py", line 970, in launch_command
    multi_gpu_launcher(args)
  File "/home/bingxing2/home/scx6002/.conda/envs/test_sd_benchmark/lib/python3.8/site-packages/accelerate/commands/launch.py", line 646, in multi_gpu_launcher
    distrib_run.run(args)
  File "/home/bingxing2/home/scx6002/.conda/envs/test_sd_benchmark/lib/python3.8/site-packages/torch/distributed/run.py", line 785, in run
    elastic_launch(
  File "/home/bingxing2/home/scx6002/.conda/envs/test_sd_benchmark/lib/python3.8/site-packages/torch/distributed/launcher/api.py", line 134, in __call__
    return launch_agent(self._config, self._entrypoint, list(args))
  File "/home/bingxing2/home/scx6002/.conda/envs/test_sd_benchmark/lib/python3.8/site-packages/torch/distributed/launcher/api.py", line 250, in launch_agent
    raise ChildFailedError(
torch.distributed.elastic.multiprocessing.errors.ChildFailedError: 
============================================================
text_to_image.py FAILED
------------------------------------------------------------
Failures:
[1]:
  time      : 2024-03-31_19:15:18
  host      : paraai-n32-h-01-agent-66.paraai-n32-h-01.com
  rank      : 1 (local_rank: 1)
  exitcode  : 2 (pid: 664524)
  error_file: <N/A>
  traceback : To enable traceback see: https://pytorch.org/docs/stable/elastic/errors.html
------------------------------------------------------------
Root Cause (first observed failure):
[0]:
  time      : 2024-03-31_19:15:18
  host      : paraai-n32-h-01-agent-66.paraai-n32-h-01.com
  rank      : 0 (local_rank: 0)
  exitcode  : 2 (pid: 664523)
  error_file: <N/A>
  traceback : To enable traceback see: https://pytorch.org/docs/stable/elastic/errors.html
============================================================
